Workbook

Sheet README
A1: 📖 REGULATORY COST CALCULATOR — README
A3: PURPOSE
A4: This workbook estimates the total regulatory cost burden imposed on affected entities by a new or existing regulation. It covers internal compliance, external compliance, delay costs, regulatory charges, and web form information collection burden.
A6: HOW TO USE THIS WORKBOOK
A7: Step 1 — Review Defaults | B7: Go to the Defaults sheet to see all assumed values (wage rates, discount rate, etc.).
A8: Step 2 — Enter Settings | B8: Go to the Settings sheet and enter your common values (number of entities, wage rate, discount rate). Leave blank to use defaults.
A9: Step 3 — Fill Cost Calculator | B9: Go to Cost Calculator and fill in yellow cells for each cost category. Name each cost item and enter quantities. Grey cells auto-populate from Settings.
A10: Step 4 — Review NPV Summary | B10: The NPV Summary sheet automatically projects costs over your chosen horizon and discounts them to present value.
A12: COLOUR GUIDE
A13: 🟡 Yellow cells | B13: YOUR INPUT — Fill these in with your values. These are the fields you need to complete.
A14: ⬜ Grey cells | B14: AUTO-POPULATED — Pulled from Settings/Defaults. You can override them in Settings.
A15: 🟢 Green cells | B15: CALCULATED — Formulas that compute automatically. Do not edit.
A16: 🟢 Dark green bars | B16: SUBTOTALS & TOTALS — Summary rows for each section.
A17: 🟦 Navy bars | B17: SECTION HEADERS — Category titles and grand totals.
A19: COST CATEGORIES
A20: 1. Internal Compliance | B20: Staff time costs: training, record-keeping, internal processes. Calculated as: Setup Hours (one-off) + Ongoing Hours × Frequency × Labour Rate × Entities × Staff.
A21: 2. External Compliance | B21: Purchased services: audits, legal advice, software, consultants. Calculated as: One-off purchase + Recurring cost × Frequency × Entities.
A22: 3. Delay Costs | B22: Costs from regulatory processing delays: standby expenses + lost income, multiplied by days of delay × number of entities.
A23: 4. Regulatory Charges | B23: Direct fees and levies: licence fees, registration charges, application fees. One-off + Recurring × Frequency × Entities.
A24: 5. Web Form Burden | B24: Time cost for entities to complete your web form. Shows gross burden, "Tell Me Once" savings (pre-existing data), and net new burden.
A26: INITIAL vs ONGOING COSTS
A27: Initial Cost (Year 1) | B27: Includes one-off setup/upfront costs PLUS the first year of recurring operating costs. This is the total cost in the first year.
A28: Ongoing Cost (Year 2+) | B28: Just the recurring annual operating costs — no setup costs. This repeats each year from Year 2 onward.
A30: KEY ASSUMPTIONS
A31: Defaults | B31: Work labour = $85/hr | Non-work labour = $37/hr | Discount rate = 7% | 20 min per form field | 1 entity, 1 staff per entity. All overridable in Settings.

Sheet Settings
A1: ⚙️ SETTINGS — Common Values
A2: Enter your common values below. These are used throughout the Cost Calculator.
A3: Yellow cells are for your input. Grey cells show defaults from the Defaults sheet.
A5: GENERAL SETTINGS
A6: Setting | B6: Your Value | C6: Default | D6: Guidance
A7: Number of affected entities | C7: =Defaults!B7 -> 1 | D7: How many regulated entities (businesses, organisations) are affected?
A8: Staff per entity | C8: =Defaults!B8 -> 1 | D8: Number of staff at each entity who will perform compliance tasks
A9: Work-related labour rate ($/hr) | C9: =Defaults!B5 -> 85 | D9: Fully loaded hourly cost of a compliance worker (incl. overheads)
A10: Non-work labour rate ($/hr) | C10: =Defaults!B6 -> 37 | D10: Opportunity cost of personal time (e.g. citizen filling out forms)
A11: Discount rate (%) | C11: =Defaults!B9 -> 0.07 | D11: Real discount rate used for NPV calculations
A12: Projection horizon (years) | C12: =Defaults!B10 -> 10 | D12: How many years to project costs (default 10)
A14: WEB FORM SETTINGS
A15: Setting | B15: Your Value | C15: Default | D15: Guidance
A16: Number of form fields | C16: =Defaults!B14 -> 10 | D16: How many data fields will your web form ask regulated entities to fill out?
A17: "Tell Me Once" fields (already held) | C17: =Defaults!B15 -> 0 | D17: Fields where government already has the data (no new burden)
A18: Minutes per form field | C18: =Defaults!B13 -> 20 | D18: Estimated minutes to complete each field. Default 20 mins — relax if simpler fields.
A20: EFFECTIVE VALUES (used in calculations)
A21: Setting | B21: Effective Value | C21: Source
A22: Entities | B22: =IF(B7="",C7,B7) -> 1 | C22: =IF(B7="","Default","User") -> Default
A23: Staff per entity | B23: =IF(B8="",C8,B8) -> 1 | C23: =IF(B8="","Default","User") -> Default
A24: Work labour rate ($/hr) | B24: =IF(B9="",C9,B9) -> 85 | C24: =IF(B9="","Default","User") -> Default
A25: Non-work labour rate ($/hr) | B25: =IF(B10="",C10,B10) -> 37 | C25: =IF(B10="","Default","User") -> Default
A26: Discount rate | B26: =IF(B11="",C11,B11) -> 0.07 | C26: =IF(B11="","Default","User") -> Default
A27: Projection years | B27: =IF(B12="",C12,B12) -> 10 | C27: =IF(B12="","Default","User") -> Default
A28: Form fields | B28: =IF(B16="",C16,B16) -> 10 | C28: =IF(B16="","Default","User") -> Default
A29: Tell Me Once fields | B29: =IF(B17="",C17,B17) -> 0 | C29: =IF(B17="","Default","User") -> Default
A30: Minutes per field | B30: =IF(B18="",C18,B18) -> 20 | C30: =IF(B18="","Default","User") -> Default

Sheet Cost Calculator
A1: 📋 REGULATORY COST CALCULATOR
A2: Fill in the yellow cells for each cost item. Leave blank to use the common values from the Settings sheet.
A3: 🟡 = Your input ⬜ = Calculated 🟢 = Subtotal / Total
A5: 1. INTERNAL COMPLIANCE COSTS
A6: Costs incurred by regulated entities performing compliance activities internally (staff time, training, record-keeping).
A7: Cost Item | B7: Setup Hours (one-off) | C7: Ongoing Hours (per occasion) | D7: Labour Cost ($/hr) | E7: Frequency (times/yr) | F7: No. of Entities | G7: Staff per Entity | H7: Initial Cost (Year 1) | I7: Ongoing Cost (Year 2+)
A8: e.g. Training staff on new regulation | D8: =Settings!B24 -> 85 | F8: =Settings!B22 -> 1 | G8: =Settings!B23 -> 1 | H8: =IF(AND(B8="",C8=""),0,(IF(B8="",0,B8)*D8*F8*G8)+(IF(C8="",0,C8)*D8*E8*F8*G8)) -> 0 | I8: =IF(C8="",0,C8*D8*E8*F8*G8) -> 0
D9: =Settings!B24 -> 85 | F9: =Settings!B22 -> 1 | G9: =Settings!B23 -> 1 | H9: =IF(AND(B9="",C9=""),0,(IF(B9="",0,B9)*D9*F9*G9)+(IF(C9="",0,C9)*D9*E9*F9*G9)) -> 0 | I9: =IF(C9="",0,C9*D9*E9*F9*G9) -> 0
D10: =Settings!B24 -> 85 | F10: =Settings!B22 -> 1 | G10: =Settings!B23 -> 1 | H10: =IF(AND(B10="",C10=""),0,(IF(B10="",0,B10)*D10*F10*G10)+(IF(C10="",0,C10)*D10*E10*F10*G10)) -> 0 | I10: =IF(C10="",0,C10*D10*E10*F10*G10) -> 0
D11: =Settings!B24 -> 85 | F11: =Settings!B22 -> 1 | G11: =Settings!B23 -> 1 | H11: =IF(AND(B11="",C11=""),0,(IF(B11="",0,B11)*D11*F11*G11)+(IF(C11="",0,C11)*D11*E11*F11*G11)) -> 0 | I11: =IF(C11="",0,C11*D11*E11*F11*G11) -> 0
D12: =Settings!B24 -> 85 | F12: =Settings!B22 -> 1 | G12: =Settings!B23 -> 1 | H12: =IF(AND(B12="",C12=""),0,(IF(B12="",0,B12)*D12*F12*G12)+(IF(C12="",0,C12)*D12*E12*F12*G12)) -> 0 | I12: =IF(C12="",0,C12*D12*E12*F12*G12) -> 0
A13: SUBTOTAL — Internal Compliance | H13: =SUM(H8:H12) -> 0 | I13: =SUM(I8:I12) -> 0
A15: 2. EXTERNAL COMPLIANCE COSTS
A16: Costs for purchasing external services, products or advice to meet compliance (e.g. audits, consultants, software).
A17: Cost Item | B17: One-off Purchase ($) | C17: Recurring Purchase ($) | D17: Times Purchased/yr | E17: No. of Entities | H17: Initial Cost (Year 1) | I17: Ongoing Cost (Year 2+)
A18: e.g. External audit fee | E18: =Settings!B22 -> 1 | H18: =IF(AND(B18="",C18=""),0,(IF(B18="",0,B18)*E18)+(IF(C18="",0,C18)*D18*E18)) -> 0 | I18: =IF(C18="",0,C18*D18*E18) -> 0
E19: =Settings!B22 -> 1 | H19: =IF(AND(B19="",C19=""),0,(IF(B19="",0,B19)*E19)+(IF(C19="",0,C19)*D19*E19)) -> 0 | I19: =IF(C19="",0,C19*D19*E19) -> 0
E20: =Settings!B22 -> 1 | H20: =IF(AND(B20="",C20=""),0,(IF(B20="",0,B20)*E20)+(IF(C20="",0,C20)*D20*E20)) -> 0 | I20: =IF(C20="",0,C20*D20*E20) -> 0
E21: =Settings!B22 -> 1 | H21: =IF(AND(B21="",C21=""),0,(IF(B21="",0,B21)*E21)+(IF(C21="",0,C21)*D21*E21)) -> 0 | I21: =IF(C21="",0,C21*D21*E21) -> 0
E22: =Settings!B22 -> 1 | H22: =IF(AND(B22="",C22=""),0,(IF(B22="",0,B22)*E22)+(IF(C22="",0,C22)*D22*E22)) -> 0 | I22: =IF(C22="",0,C22*D22*E22) -> 0
A23: SUBTOTAL — External Compliance | H23: =SUM(H18:H22) -> 0 | I23: =SUM(I18:I22) -> 0
A25: 3. DELAY COSTS
A26: Costs incurred due to regulatory processing delays (standby expenses, lost income while waiting for approvals).
A27: Cost Item | B27: Standby Cost ($/day) | C27: Lost Income ($/day) | D27: Days of Delay | E27: No. of Entities | F27: Frequency (times/yr) | H27: Initial Cost (Year 1) | I27: Ongoing Cost (Year 2+)
A28: e.g. Waiting for licence approval | E28: =Settings!B22 -> 1 | H28: =IF(AND(B28="",C28=""),0,(IF(B28="",0,B28)+IF(C28="",0,C28))*D28*E28*IF(F28="",1,F28)) -> 0 | I28: =IF(AND(B28="",C28=""),0,(IF(B28="",0,B28)+IF(C28="",0,C28))*D28*E28*IF(F28="",1,F28)) -> 0
E29: =Settings!B22 -> 1 | H29: =IF(AND(B29="",C29=""),0,(IF(B29="",0,B29)+IF(C29="",0,C29))*D29*E29*IF(F29="",1,F29)) -> 0 | I29: =IF(AND(B29="",C29=""),0,(IF(B29="",0,B29)+IF(C29="",0,C29))*D29*E29*IF(F29="",1,F29)) -> 0
E30: =Settings!B22 -> 1 | H30: =IF(AND(B30="",C30=""),0,(IF(B30="",0,B30)+IF(C30="",0,C30))*D30*E30*IF(F30="",1,F30)) -> 0 | I30: =IF(AND(B30="",C30=""),0,(IF(B30="",0,B30)+IF(C30="",0,C30))*D30*E30*IF(F30="",1,F30)) -> 0
E31: =Settings!B22 -> 1 | H31: =IF(AND(B31="",C31=""),0,(IF(B31="",0,B31)+IF(C31="",0,C31))*D31*E31*IF(F31="",1,F31)) -> 0 | I31: =IF(AND(B31="",C31=""),0,(IF(B31="",0,B31)+IF(C31="",0,C31))*D31*E31*IF(F31="",1,F31)) -> 0
E32: =Settings!B22 -> 1 | H32: =IF(AND(B32="",C32=""),0,(IF(B32="",0,B32)+IF(C32="",0,C32))*D32*E32*IF(F32="",1,F32)) -> 0 | I32: =IF(AND(B32="",C32=""),0,(IF(B32="",0,B32)+IF(C32="",0,C32))*D32*E32*IF(F32="",1,F32)) -> 0
A33: SUBTOTAL — Delay Costs | H33: =SUM(H28:H32) -> 0 | I33: =SUM(I28:I32) -> 0
A35: 4. REGULATORY CHARGES
A36: Direct fees, levies, and charges imposed by the regulator (licence fees, registration charges, penalties).
A37: Cost Item | B37: One-off Charge ($) | C37: Recurring Charge ($) | D37: Times Paid/yr | E37: No. of Entities | H37: Initial Cost (Year 1) | I37: Ongoing Cost (Year 2+)
A38: e.g. Annual licence fee | E38: =Settings!B22 -> 1 | H38: =IF(AND(B38="",C38=""),0,(IF(B38="",0,B38)*E38)+(IF(C38="",0,C38)*D38*E38)) -> 0 | I38: =IF(C38="",0,C38*D38*E38) -> 0
E39: =Settings!B22 -> 1 | H39: =IF(AND(B39="",C39=""),0,(IF(B39="",0,B39)*E39)+(IF(C39="",0,C39)*D39*E39)) -> 0 | I39: =IF(C39="",0,C39*D39*E39) -> 0
E40: =Settings!B22 -> 1 | H40: =IF(AND(B40="",C40=""),0,(IF(B40="",0,B40)*E40)+(IF(C40="",0,C40)*D40*E40)) -> 0 | I40: =IF(C40="",0,C40*D40*E40) -> 0
E41: =Settings!B22 -> 1 | H41: =IF(AND(B41="",C41=""),0,(IF(B41="",0,B41)*E41)+(IF(C41="",0,C41)*D41*E41)) -> 0 | I41: =IF(C41="",0,C41*D41*E41) -> 0
E42: =Settings!B22 -> 1 | H42: =IF(AND(B42="",C42=""),0,(IF(B42="",0,B42)*E42)+(IF(C42="",0,C42)*D42*E42)) -> 0 | I42: =IF(C42="",0,C42*D42*E42) -> 0
A43: SUBTOTAL — Regulatory Charges | H43: =SUM(H38:H42) -> 0 | I43: =SUM(I38:I42) -> 0
A45: 5. WEB FORM BURDEN (Information Collection)
...

Sheet NPV Summary
A1: 📈 NPV SUMMARY — Multi-Year Projection
A2: This sheet projects regulatory costs over your chosen horizon and calculates the Net Present Value (NPV).
A4: KEY PARAMETERS | B4: Value
A5: Discount rate | B5: =Settings!B26 -> 0.07
A6: Projection years | B6: =Settings!B27 -> 10
A7: Year 1 total cost (Initial) | B7: ='Cost Calculator'!H56 -> 283.33333
A8: Ongoing annual cost (Year 2+) | B8: ='Cost Calculator'!I56 -> 283.33333
A10: YEAR-BY-YEAR PROJECTION
A11: Year | B11: Nominal Cost | C11: Discount Factor | D11: Present Value | E11: Cumulative PV | F11: Category
A12: 1 | B12: =$B$7 -> 283.33333 | C12: =1/(1+$B$5)^(A12-1) -> 1 | D12: =B12*C12 -> 283.33333 | E12: =D12 -> 283.33333 | F12: Initial
A13: =A12+1 -> 2 | B13: =IF(A13>$B$6,"",$B$8) -> 283.33333 | C13: =IF(A13>$B$6,"",1/(1+$B$5)^(A13-1)) -> 0.93457944 | D13: =IF(A13>$B$6,"",B13*C13) -> 264.79751 | E13: =IF(A13>$B$6,"",E12+D13) -> 548.13084 | F13: =IF(A13>$B$6,"","Ongoing") -> Ongoing
A14: =A13+1 -> 3 | B14: =IF(A14>$B$6,"",$B$8) -> 283.33333 | C14: =IF(A14>$B$6,"",1/(1+$B$5)^(A14-1)) -> 0.87343873 | D14: =IF(A14>$B$6,"",B14*C14) -> 247.47431 | E14: =IF(A14>$B$6,"",E13+D14) -> 795.60515 | F14: =IF(A14>$B$6,"","Ongoing") -> Ongoing
A15: =A14+1 -> 4 | B15: =IF(A15>$B$6,"",$B$8) -> 283.33333 | C15: =IF(A15>$B$6,"",1/(1+$B$5)^(A15-1)) -> 0.81629788 | D15: =IF(A15>$B$6,"",B15*C15) -> 231.2844 | E15: =IF(A15>$B$6,"",E14+D15) -> 1026.8895 | F15: =IF(A15>$B$6,"","Ongoing") -> Ongoing
A16: =A15+1 -> 5 | B16: =IF(A16>$B$6,"",$B$8) -> 283.33333 | C16: =IF(A16>$B$6,"",1/(1+$B$5)^(A16-1)) -> 0.76289521 | D16: =IF(A16>$B$6,"",B16*C16) -> 216.15364 | E16: =IF(A16>$B$6,"",E15+D16) -> 1243.0432 | F16: =IF(A16>$B$6,"","Ongoing") -> Ongoing
A17: =A16+1 -> 6 | B17: =IF(A17>$B$6,"",$B$8) -> 283.33333 | C17: =IF(A17>$B$6,"",1/(1+$B$5)^(A17-1)) -> 0.71298618 | D17: =IF(A17>$B$6,"",B17*C17) -> 202.01275 | E17: =IF(A17>$B$6,"",E16+D17) -> 1445.0559 | F17: =IF(A17>$B$6,"","Ongoing") -> Ongoing
A18: =A17+1 -> 7 | B18: =IF(A18>$B$6,"",$B$8) -> 283.33333 | C18: =IF(A18>$B$6,"",1/(1+$B$5)^(A18-1)) -> 0.66634222 | D18: =IF(A18>$B$6,"",B18*C18) -> 188.79696 | E18: =IF(A18>$B$6,"",E17+D18) -> 1633.8529 | F18: =IF(A18>$B$6,"","Ongoing") -> Ongoing
A19: =A18+1 -> 8 | B19: =IF(A19>$B$6,"",$B$8) -> 283.33333 | C19: =IF(A19>$B$6,"",1/(1+$B$5)^(A19-1)) -> 0.62274974 | D19: =IF(A19>$B$6,"",B19*C19) -> 176.44576 | E19: =IF(A19>$B$6,"",E18+D19) -> 1810.2987 | F19: =IF(A19>$B$6,"","Ongoing") -> Ongoing
A20: =A19+1 -> 9 | B20: =IF(A20>$B$6,"",$B$8) -> 283.33333 | C20: =IF(A20>$B$6,"",1/(1+$B$5)^(A20-1)) -> 0.5820091 | D20: =IF(A20>$B$6,"",B20*C20) -> 164.90258 | E20: =IF(A20>$B$6,"",E19+D20) -> 1975.2012 | F20: =IF(A20>$B$6,"","Ongoing") -> Ongoing
A21: =A20+1 -> 10 | B21: =IF(A21>$B$6,"",$B$8) -> 283.33333 | C21: =IF(A21>$B$6,"",1/(1+$B$5)^(A21-1)) -> 0.54393374 | D21: =IF(A21>$B$6,"",B21*C21) -> 154.11456 | E21: =IF(A21>$B$6,"",E20+D21) -> 2129.3158 | F21: =IF(A21>$B$6,"","Ongoing") -> Ongoing
A22: =A21+1 -> 11 | B22: =IF(A22>$B$6,"",$B$8) | C22: =IF(A22>$B$6,"",1/(1+$B$5)^(A22-1)) | D22: =IF(A22>$B$6,"",B22*C22) | E22: =IF(A22>$B$6,"",E21+D22) | F22: =IF(A22>$B$6,"","Ongoing")
A23: =A22+1 -> 12 | B23: =IF(A23>$B$6,"",$B$8) | C23: =IF(A23>$B$6,"",1/(1+$B$5)^(A23-1)) | D23: =IF(A23>$B$6,"",B23*C23) | E23: =IF(A23>$B$6,"",E22+D23) | F23: =IF(A23>$B$6,"","Ongoing")
A24: =A23+1 -> 13 | B24: =IF(A24>$B$6,"",$B$8) | C24: =IF(A24>$B$6,"",1/(1+$B$5)^(A24-1)) | D24: =IF(A24>$B$6,"",B24*C24) | E24: =IF(A24>$B$6,"",E23+D24) | F24: =IF(A24>$B$6,"","Ongoing")
... A31: =A30+1 -> 20 | B31: =IF(A31>$B$6,"",$B$8) | C31: =IF(A31>$B$6,"",1/(1+$B$5)^(A31-1)) | D31: =IF(A31>$B$6,"",B31*C31) | E31: =IF(A31>$B$6,"",E30+D31) | F31: =IF(A31>$B$6,"","Ongoing")
A33: NET PRESENT VALUE (NPV) | D33: =SUM(D12:D31) -> 2129.3158
A35: COST BREAKDOWN BY CATEGORY | B35: Initial (Yr 1) | C35: Ongoing (Yr 2+) | D35: % of Initial
A36: 1. Internal Compliance | B36: ='Cost Calculator'!H13 -> 0 | C36: ='Cost Calculator'!I13 -> 0 | D36: =IF(B41=0,0,B36/B41) -> 0
A37: 2. External Compliance | B37: ='Cost Calculator'!H23 -> 0 | C37: ='Cost Calculator'!I23 -> 0 | D37: =IF(B41=0,0,B37/B41) -> 0
A38: 3. Delay Costs | B38: ='Cost Calculator'!H33 -> 0 | C38: ='Cost Calculator'!I33 -> 0 | D38: =IF(B41=0,0,B38/B41) -> 0
A39: 4. Regulatory Charges | B39: ='Cost Calculator'!H43 -> 0 | C39: ='Cost Calculator'!I43 -> 0 | D39: =IF(B41=0,0,B39/B41) -> 0
A40: 5. Web Form Burden | B40: ='Cost Calculator'!H54 -> 283.33333 | C40: ='Cost Calculator'!I54 -> 283.33333 | D40: =IF(B41=0,0,B40/B41) -> 1
A41: TOTAL | B41: =SUM(B36:B40) -> 283.33333 | C41: =SUM(C36:C40) -> 283.33333 | D41: =SUM(D36:D40) -> 1

Sheet Defaults
A1: DEFAULTS & ASSUMPTIONS
A2: This sheet contains the default values used throughout the workbook.
A4: Parameter | B4: Default Value | C4: Notes
A5: Work-related labour rate ($/hr) | B5: 85 | C5: Fully loaded cost including on-costs
A6: Non-work-related labour rate ($/hr) | B6: 37 | C6: Opportunity cost of personal/citizen time
A7: Number of affected entities | B7: 1 | C7: Override in Settings
A8: Staff per entity | B8: 1 | C8: Default assumption
A9: Discount rate | B9: 0.07 | C9: Real discount rate for NPV calculations
A10: Projection horizon (years) | B10: 10 | C10: Number of years for NPV projection
A12: Web Form Defaults
A13: Minutes per form field | B13: 20 | C13: Time to complete one field on a web form
A14: Number of form fields | B14: 10 | C14: Total fields on the regulatory web form
A15: Tell Me Once fields (pre-existing data) | B15: 0 | C15: Fields where data is already held by government
A17: Frequency Multipliers
A18: Monthly | B18: 12 | C18: Times per year
A19: Quarterly | B19: 4 | C19: Times per year
A20: Annually | B20: 1 | C20: Times per year
